<?xml version="1.0"?>
<robot xmlns:xacro="http://www.ros.org/wiki/xacro" name="round_bot">

  <xacro:include filename="$(find round_bot)/description/inertial_xacros.xacro"/> 
  
  <link name="base_footprint"/> 
  
  <joint name="chassis_joint" type="fixed">
    <parent link="base_footprint"/>
    <child link="chassis"/>
    <origin xyz="0.0 0.0 0.0" rpy="0.0 0.0 0.0"/>
  </joint>
  
  <link name="chassis">
    <visual>
      <origin xyz="0.0 0.0 0.12" rpy="0.0 0.0 0.0"/>
      <geometry>
        <cylinder radius="${chassis_radius}" length="${chassis_length}"/>
      </geometry>
      <material name ="Orange">
        <color rgba = "1.0 0.3 0.1 1.0"/>
      </material>
    </visual>
    <collision>
      <origin xyz="0.0 0.0 0.12" rpy="0.0 0.0 0.0"/>
      <geometry>
        <cylinder radius="${chassis_radius}" length="${chassis_length}"/>
      </geometry>
      <contact_coefficients mu1 = "1" mu2 = "1" kp = "1e+13.0" kd = "1.0"/>
    </collision>
    <xacro:inertial_chassis_cylinder chassis_mass="${chassis_mass}" chassis_length="${chassis_length}" chassis_radius="${chassis_radius}">
      <origin xyz="0 0 0.12" rpy="0 0 0"/>
    </xacro:inertial_chassis_cylinder>
  </link>

  <gazebo reference = "chassis">
    <material>Gazebo/Orange</material>
  </gazebo>

  <joint name="left_wheel_joint" type="continuous">
    <parent link="chassis"/>
    <child link="left_wheel"/>
    <axis xyz="0 0 1.0"/>
    <origin xyz="0.0 0.18 0.075" rpy="-1.57 0.0 0.0"/>
  </joint>

  <link name="left_wheel">
    <visual>
      <geometry>
        <cylinder radius="${wheel_radius}" length="${wheel_length}"/>
      </geometry>
      <material name = "Red">
        <color rgba = "1.0 0.0 0.0 1.0"/>
      </material>
    </visual>
    <collision>
      <geometry>
        <sphere radius="${wheel_radius}"/>
      </geometry>
      <contact_coefficients mu1 = "0" kp = "1000.0" kd = "1.0"/>
    </collision>
    <xacro:inertial_wheel_cylinder wheel_mass="${wheel_mass}" wheel_length="${wheel_length}" wheel_radius="${wheel_radius}">
      <origin xyz="0 0 0" rpy="0 0 0"/>
    </xacro:inertial_wheel_cylinder>
  </link>

  <gazebo reference = "left_wheel">
    <material>Gazebo/Red</material>
  </gazebo> 

  <joint name="right_wheel_joint" type="continuous">
    <parent link="chassis"/>
    <child link="right_wheel"/>
    <axis xyz="0.0 0.0 1.0"/>
    <origin xyz="0.0 -0.18 0.075" rpy="-1.57 0.0 0.0"/>
  </joint>

  <link name="right_wheel">
    <visual>
      <geometry>
        <cylinder radius="${wheel_radius}" length="${wheel_length}"/>
      </geometry>
      <material name = "Red">
        <color rgba = "1.0 0.0 0.0 1.0"/>
      </material>
    </visual>
    <collision>
      <geometry>
        <sphere radius="${wheel_radius}"/>
      </geometry>
      <contact_coefficients mu = "0" kp = "1000.0" kd = "1.0"/>
    </collision>
    <xacro:inertial_wheel_cylinder wheel_mass="${wheel_mass}" wheel_length="${wheel_length}" wheel_radius="${wheel_radius}">
      <origin xyz="0 0 0" rpy="0 0 0"/>
    </xacro:inertial_wheel_cylinder>
  </link>

  <gazebo reference = "right_wheel">
    <slip1 value="0.5" />
    <slip2 value="0.5" />
    <material>Gazebo/Red</material>
  </gazebo> 

  <joint name="front_caster_joint" type="fixed">
    <parent link="chassis"/>
    <child link="front_caster_link"/>
    <origin xyz="0.18 0.0 0.0452" rpy="0 0 0"/>
    <mu1 value="0.001"/>
    <mu2 value="0.001"/>
  </joint>

  <link name="front_caster_link">
    <visual>                     
      <geometry>
        <sphere radius="${caster_radius}"/>
      </geometry>
      <material name="Red">
        <color rgba="1.0 0.0 0.0 1.0"/>
      </material>
    </visual>
    <collision>
      <geometry>
        <sphere radius="${caster_radius}"/>
      </geometry>
      <contact_coefficients mu="0" kp="1000.0" kd="1.0"/>
    </collision>

    <xacro:inertial_sphere caster_mass="${caster_mass}" caster_radius="${caster_radius}">
      <origin xyz="0 0 0" rpy="0 0 0"/>
    </xacro:inertial_sphere>
  </link> 

  <gazebo reference = "front_caster_link">
    <material>Gazebo/Red</material>
  </gazebo> 

  <joint name="back_caster_joint" type="fixed">
    <parent link="chassis"/>
    <child link="back_caster_link"/>
    <origin xyz="-0.18 0.0 0.0452" rpy="0 0 0"/>
    <mu1 value="0.001"/>
    <mu2 value="0.001"/>
  </joint>

  <link name="back_caster_link">
    <visual>                     
      <geometry>
        <sphere radius="${caster_radius}"/>
      </geometry>
      <material name="Red">
        <color rgba="1.0 0.0 0.0 1.0"/>
      </material>
    </visual>
    <collision>
      <geometry>
        <sphere radius="${caster_radius}"/>
      </geometry>
      <contact_coefficients mu="0" kp="1000.0" kd="1.0"/>
    </collision>

    <xacro:inertial_sphere caster_mass="${caster_mass}" caster_radius="${caster_radius}">
      <origin xyz="0 0 0" rpy="0 0 0"/>
    </xacro:inertial_sphere>
  </link> 

  <gazebo reference = "back_caster_link">
    <material>Gazebo/Red</material>
  </gazebo> 

  <joint name="mount_joint" type="fixed">
    <parent link="chassis"/>
    <child link="mount_link"/>
    <origin xyz="0.15 0.0 0.18" rpy="0.0 0.0 0.0"/>
  </joint>

  <link name="mount_link">
    <visual>                     
      <geometry>
        <cylinder radius="${mount_radius}" length="${mount_length}"/>
      </geometry>
      <material name="Black">
        <color rgba="0.0 0.0 0.0 1.0"/>
      </material>
    </visual>
    <collision>
      <geometry>
        <cylinder radius="${mount_radius}" length="${mount_length}"/>
      </geometry>
    </collision>
    <xacro:inertial_mount_cylinder mount_mass="${mount_mass}" mount_length="${mount_length}" mount_radius="${mount_radius}"> 
      <origin xyz="0 0 0" rpy="0 0 0"/>
    </xacro:inertial_mount_cylinder>
  </link> 

  <gazebo reference = "mount_link">
    <material>Gazebo/Black</material>
  </gazebo>

  <link name="camera_link">
    <visual>  
      <geometry>
        <box size="0.010 0.05 0.05"/>
      </geometry>
      <material name="blue">
        <color rgba="0 0 1 1"/>
      </material>
    </visual>
  </link>

  <joint name="camera_joint" type="fixed">
    <origin xyz="0.25 0.0 0.125" rpy="0 0 0"/>
    <parent link="chassis"/>
    <child link="camera_link"/>
  </joint>

  <joint name="camera_optical_joint" type="fixed">
    <origin xyz="0.0 0.0 0.0" rpy="-1.57 0.0 -1.57"/>
    <parent link="camera_link"/>
    <child link="camera_link_optical"/>
  </joint>

  <link name="camera_link_optical">
      
  </link>

  <!-- depth camera -->
  <gazebo reference="camera_link">
    <material>Gazebo/Blue</material>
    <sensor name="depth_camera" type="depth">
        <pose> 0 0 0 0 0 0 </pose>
        <visualize>true</visualize>
        <update_rate>5</update_rate>
        <camera>
          <horizontal_fov>1.089</horizontal_fov>
          <image>
            <format>B8G8R8</format>
            <width>640</width>
            <height>480</height>
          </image>
          <clip>
            <near>0.05</near>
            <far>8.0</far>
          </clip>
        </camera>
        <plugin name="camera_controller" filename="libgazebo_ros_camera.so">
          <frame_name>camera_link_optical</frame_name>
          <min_depth>0.1</min_depth>
          <max_depth>100.0</max_depth>
        </plugin>
      </sensor>
  </gazebo>

  <link name="lidar_link">
    <visual>
      <geometry>
        <cylinder radius="${lidar_radius}" length="${lidar_length}"/>
      </geometry>
      <material name="red">
        <color rgba="1 0 0 1"/>
      </material>
    </visual>

    <collision>
      <geometry>
        <cylinder radius="${lidar_radius}" length="${lidar_length}"/>
      </geometry>
    </collision>
    <xacro:inertial_lidar_cylinder lidar_mass="0.1" lidar_length="0.07" lidar_radius="0.1"> 
      <origin xyz="0 0 0" rpy="0 0 0"/>
    </xacro:inertial_lidar_cylinder>
  </link>

  <joint name="lidar_joint" type="fixed">
    <origin xyz="0.0 0 0.03" rpy="0 0.0 0.0"/>
    <parent link="mount_link"/>
    <child link="lidar_link"/>
  </joint>

  <!-- 3d lidar -->
  <gazebo reference="lidar_link">
    <material>Gazebo/Red</material>
    <sensor type="ray" name="3d_lidar">
      <pose>0 0 0 0 0 0</pose>
      <visualize>true</visualize>
      <ray>
        <scan>
          <horizontal>
            <samples>180</samples>
            <resolution>1</resolution>
              <min_angle>-3.14159</min_angle>
              <max_angle>3.14159</max_angle>
          </horizontal>
          <vertical>
            <samples>10</samples>
            <resolution>1</resolution>
            <min_angle>-0.3</min_angle>
            <max_angle>0.3</max_angle>
          </vertical>
        </scan>
        <range>
          <min>0.3</min>
          <max>2.5</max>
          <resolution>0.01</resolution>
        </range>
      </ray>
      <plugin name="gazebo_ros_block_laser_controller_1" filename="libgazebo_ros_velodyne_laser.so">
        <ros>
          <remapping>~/out:=velodyne_points</remapping>  
          <qos>
            <topic name="velodyne_points">
              <publisher>
                <reliability>reliable</reliability>
              </publisher>
            </topic>
          </qos>                                                                                                                         
        </ros>
        <output_type>sensor_msgs/PointCloud2</output_type>
        <alwaysOn>true</alwaysOn>
        <updateRate>10</updateRate>
        <topicName>velodyne_points</topicName>
        <frame_name>lidar_link</frame_name>
      </plugin>
    </sensor>
  </gazebo>

  <!-- 2d lidar -->
  <gazebo reference="lidar_link">
    <material>Gazebo/Red</material>
      <sensor name="2d_lidar" type="ray">
      <pose> 0 0 0 0 0 0 </pose>
      <visualize>true</visualize>
      <update_rate>10.0</update_rate>
      <ray>
        <scan>
          <horizontal>
            <samples>360</samples>
            <resolution>1.000000</resolution>
            <min_angle>-3.14159</min_angle>
            <max_angle>3.14159</max_angle>
          </horizontal>
        </scan>
        <range>
          <min>0.3</min>
          <max>2.5</max>
          <resolution>0.1</resolution>
        </range>
        <noise>
          <type>gaussian</type>
          <mean>0.0</mean>
          <stddev>0.01</stddev>
        </noise>
      </ray>
      <plugin name="gazebo_ros_block_laser_controller_2" filename="libgazebo_ros_ray_sensor.so">
        <ros>
          <remapping>~/out:=scan</remapping>
        </ros>
        <output_type>sensor_msgs/LaserScan</output_type>
        <frame_name>lidar_link</frame_name>
      </plugin>
    </sensor>
  </gazebo>

  <gazebo>
    <plugin name='diff_drive' filename='libgazebo_ros_diff_drive.so'>
      <update_rate>10</update_rate>
      <left_joint>left_wheel_joint</left_joint>
      <right_joint>right_wheel_joint</right_joint>
      <wheel_separation>0.36</wheel_separation>
      <wheel_diameter>0.16</wheel_diameter>
      <max_wheel_torque>10</max_wheel_torque>
      <max_wheel_acceleration>1.0</max_wheel_acceleration>
      <publish_odom>true</publish_odom>
      <publish_odom_tf>true</publish_odom_tf>
      <publish_wheel_tf>true</publish_wheel_tf>
      <odometry_source>1</odometry_source>
      <odometry_frame>odom</odometry_frame>
      <robot_base_frame>base_footprint</robot_base_frame>
    </plugin>
  </gazebo> 
</robot>